Workbook
Name Slicer_Category: #N/A
Name Slicer_Region: #N/A
Name Slicer_Store_name: #N/A

Sheet Customer_Dim
A1: Customer_ID | B1: Name | C1: Age | D1: Gender | E1: City | F1: State | G1: Country | H1: Loyalty_Level
A2: CUST1000 | B2: sheena bonilla | C2: 55 | D2: Male | E2: Donaldton | F2: North Carolina | G2: USA
A3: CUST1001 | B3: Eugene Nelson | C3: 26 | D3: Female | E3: Phillipsmouth | F3: North Dakota | G3: USA | H3: Platinum
A4: CUST1002 | B4: dr. Benjamin Price | C4: 29 | D4: Female | E4: Kylebury | F4: Alabama | G4: USA | H4: Platinum
A5: CUST1003 | B5: jeremy harris | C5: 59 | D5: Female | E5: Thomastown | F5: Ohio | G5: USA | H5: Bronze
A6: CUST1004 | B6: Caroline Collins | C6: 64 | D6: Female | E6: Nicholasshire | F6: California | G6: USA | H6: Silver
A7: CUST1005 | B7: Christine Vaughn | C7: 24 | D7: Male | E7: East Amandamouth | F7: Oregon | G7: USA | H7: Bronze
A8: CUST1006 | B8: Amber Jackson | C8: 29 | D8: Female | E8: Deborahborough | F8: South Dakota | G8: USA | H8: Platinum
A9: CUST1007 | B9: Daniel Boyd | C9: 29 | D9: Female | E9: West Pamelafurt | F9: West Virginia | G9: USA | H9: Bronze
A10: CUST1008 | B10: Melissa Howard | C10: 53 | D10: Female | E10: Maynardton | F10: New Hampshire | G10: USA | H10: Gold
A11: CUST1009 | B11: Ms. Maria Leach | C11: 64 | D11: Male | E11: Melissashire | F11: Pennsylvania | G11: USA | H11: Platinum
A12: CUST1010 | B12: Dominic Page | C12: 53 | D12: Male | E12: Port Michaelburgh | F12: Pennsylvania | G12: USA | H12: Bronze
A13: CUST1011 | B13: Brian Lopez | C13: 28 | D13: Female | E13: East Krista | F13: New York | G13: USA | H13: Gold
A14: CUST1012 | B14: Kenneth Lambert | C14: 55 | D14: Female | E14: North Kathryn | F14: Kansas | G14: USA | H14: Platinum
... A19: CUST1017 | B19: Adam Cruz | C19: 60 | D19: Female | E19: Brandonville | F19: Georgia | G19: USA | H19: Platinum
A20: CUST1018 | B20: Rhonda Moss | C20: 43 | D20: Male | E20: South William | F20: Kansas | G20: USA
A21: CUST1019 | B21: Michael Torres | C21: 46 | D21: Female | E21: Gonzalezfort | F21: New Jersey | G21: USA | H21: Platinum
A22: CUST1020 | B22: Bridget Allen | C22: 59 | D22: Male | E22: Lake Shaneburgh | F22: Delaware | G22: USA | H22: Silver
A23: CUST1021 | B23: Jeff Martinez | C23: 36 | D23: Female | E23: Smithburgh | F23: Oklahoma | G23: USA | H23: Gold
A24: CUST1022 | B24: paul fox | C24: 33 | D24: Female | E24: Michaelton | F24: Hawaii | G24: USA | H24: Silver
A25: CUST1023 | B25: Jonathan Steele | C25: 52 | D25: Female | E25: Molinabury | F25: Oregon | G25: USA | H25: Silver
A26: CUST1024 | B26: Heather Collins | C26: 40 | D26: Male | E26: Rogerschester | F26: Idaho | G26: USA | H26: Platinum
A27: CUST1025 | B27: Diana Taylor | C27: 59 | D27: Female | E27: Vasqueztown | F27: California | G27: USA | H27: Bronze
A28: CUST1026 | B28: Amber Carlson | C28: 18 | D28: Female | E28: East Michellemouth | F28: Missouri | G28: USA | H28: Gold
A29: CUST1027 | B29: Leslie Johnson | C29: 31 | D29: Male | E29: Mollyshire | F29: Utah | G29: USA
A30: CUST1028 | B30: Joshua Ryan | C30: 27 | D30: Female | E30: New David | F30: New Jersey | G30: USA | H30: Platinum
A31: CUST1029 | B31: David Arnold | C31: 54 | D31: Female | E31: East Jennifer | F31: California | G31: USA | H31: Silver
A32: CUST1030 | B32: Jessica Acevedo | C32: 64 | D32: Female | E32: Amybury | F32: Pennsylvania | G32: USA | H32: Bronze
A33: CUST1031 | B33: Sarah Vance | C33: 41 | D33: Male | E33: Johnsonville | F33: Oregon | G33: USA | H33: Silver
A34: CUST1032 | B34: Mike Jennings | C34: 48 | D34: Female | E34: Fostermouth | F34: Arizona | G34: USA | H34: Gold
A35: CUST1033 | B35: Robert Jones DDS | C35: 25 | D35: Male | E35: Tristanton | F35: Oklahoma | G35: USA | H35: Platinum
A36: CUST1034 | B36: Christopher Olson | C36: 27 | D36: Female | E36: West Richard | F36: Maryland | G36: USA | H36: Platinum
A37: CUST1035 | B37: Rachel Myers | C37: 52 | D37: Male | E37: Robertberg | F37: North Dakota | G37: USA | H37: Silver
A38: CUST1036 | B38: Thomas Phillips | C38: 20 | D38: Female | E38: Luisfurt | F38: Georgia | G38: USA | H38: Gold
A39: CUST1037 | B39: Christopher Carter | C39: 27 | D39: Female | E39: Brendastad | F39: South Dakota | G39: USA
A40: CUST1038 | B40: Deanna Simpson | C40: 35 | D40: Female | E40: Brownport | F40: North Dakota | G40: USA | H40: Bronze
A41: CUST1039 | B41: Tonya Reynolds | C41: 55 | D41: Female | E41: Darleneton | F41: Michigan | G41: USA | H41: Gold
A42: CUST1040 | B42: Eric Vega | C42: 50 | D42: Male | E42: Williamsonland | F42: Kansas | G42: USA | H42: Gold
A43: CUST1041 | B43: James Gibbs | C43: 21 | D43: Male | E43: Mooneyshire | F43: Alaska | G43: USA | H43: Platinum
A44: CUST1042 | B44: William Martin | C44: 19 | D44: Male | E44: Ryanburgh | F44: Connecticut | G44: USA | H44: Platinum
...

Sheet Product_Dim
A1: Product_ID | B1: Product_Name | C1: Category | D1: Sub_Category | E1: Brand | F1: Cost | G1: Stock
A2: PROD0 | B2: Brother Laser Printer | C2: Electronics | D2: Computer | E2: Hunt Inc | F2: 112.42 | G2: 416
A3: PROD1 | B3: Men's Graphic T-Shirt | C3: Clothing | D3: Tops | E3: Terry-Moore | F3: 342.56 | G3: 181
A4: PROD2 | B4: Women's Casual Hoodie | C4: Clothing | D4: Outerwear | E4: Sims Inc | G4: 352
A5: P-3 | B5: Men's Running Jacket | C5: Clothing | D5: Outerwear | E5: Pineda Ltd | F5: 364.67 | G5: 452
A6: PROD4 | B6: Women's Yoga Pants | C6: Clothing | D6: Bottoms | E6: Gonzales-Davis | F6: 306.46 | G6: 487
A7: PROD5 | B7: Men's Leather Belt | C7: Clothing | D7: Accessories | E7: Baldwin, Garza and Gonzalez | F7: 261 | G7: 59
A8: PROD6 | B8: Herbal Face Moisturizer | C8: Beauty | D8: Skincare | E8: Davidson PLC | F8: 312.8 | G8: 350
A9: PROD7 | B9: LED Table Lamp | C9: Home | D9: Lighting | E9: Harrell LLC | F9: 218.86 | G9: 170
A10: PROD8 | B10: Wireless Bluetooth Earbuds | C10: Electronics | D10: Audio | E10: Perez-Johnston | F10: 439.07 | G10: 142
A11: PROD9 | B11: Adjustable Dumbbell Set | C11: Sports | D11: Fitness | E11: Hill PLC | F11: 495.72 | G11: 323
A12: PROD10 | B12: Ceramic Kitchen Bowl Set | C12: Home | D12: Kitchen | E12: Hamilton Group | F12: 298.86 | G12: 308
A13: PROD11 | B13: HD Smart TV Stick | C13: Electronics | D13: Accessories | E13: Gibson, Hobbs and Weaver | F13: 449.4
A14: PROD12 | B14: Hair Strengthening Shampoo | C14: Beauty | D14: Haircare | E14: Rice LLC | F14: 115.82 | G14: 460
A15: PROD13 | B15: USB-C Fast Charger | C15: Electronics | D15: Accessories | E15: Dawson-Perkins | F15: 242.23 | G15: 453
A16: PROD14 | B16: Decorative Wall Mirror | C16: Home | D16: Decor | E16: Luna, Anderson and Bowman | F16: 48.01 | G16: 439
A17: PROD15 | B17: 4K Home Projector | C17: Electronics | D17: Appliances | E17: Thomas LLC | F17: 465.34 | G17: 301
A18: P-16 | B18: Beard Grooming Kit | C18: Beauty | D18: Grooming | E18: Erickson-Green | F18: 337.42 | G18: 256
A19: PROD17 | B19: Soccer Training Cone Set | C19: Sports | D19: Accessories | E19: Ford, Murphy and Wilson | F19: 144.53 | G19: 367
A20: PROD18 | B20: Women's Denim Jeans | C20: Clothing | D20: Bottoms | E20: Guerra-Hendrix | G20: 343
A21: PROD19 | B21: Knee Support Brace | C21: Sports | D21: Equipment | E21: May-Reese | F21: 21.34 | G21: 65
A22: PROD20 | B22: Outdoor Sports Water Bottle | C22: Sports | D22: Accessories | E22: Soto-Ellis | F22: 131.51
A23: PROD21 | B23: Multi-Purpose Storage Box | C23: Home | D23: Storage | E23: Gardner-Montes | F23: 123.46 | G23: 76
A24: PROD22 | B24: Carbon Fiber Tennis Racket | C24: Sports | D24: Equipment | E24: Flores, Pineda and Rodriguez | F24: 484.62 | G24: 432
A25: PROD23 | B25: Men's Formal Shirt | C25: Clothing | D25: Tops | E25: Moon, Mora and Santos | G25: 360
A26: PROD24 | B26: Foldable Camping Chair | C26: Sports | D26: Outdoor | E26: Cook Ltd | F26: 166.06 | G26: 340
A27: PROD25 | B27: Women's Scarf Set | C27: Clothing | D27: Accessories | E27: Brown and Sons | F27: 174.02 | G27: 268
A28: PROD26 | B28: Wireless Bluetooth Speaker | C28: Electronics | D28: Audio | E28: Reed-Schmidt | F28: 322.41 | G28: 213
A29: PROD27 | B29: Decorative Floor Vase | C29: Home | D29: Decor | E29: Khan, Jones and Paul | G29: 378
A30: PROD28 | B30: Sports Stopwatch Timer | C30: Sports | D30: Accessories | E30: Burns-Hansen | F30: 38.76 | G30: 137
A31: PROD29 | B31: Fabric Sofa Throw Blanket | C31: Home | D31: Decor | E31: Hoffman Group | F31: 218.48 | G31: 276
A32: PROD30 | B32: Stainless Steel Cutlery Set | C32: Home | D32: Kitchen | E32: Stevens, Fernandez and Martin | F32: 19.52 | G32: 57
A33: PROD31 | B33: Basketball | C33: Sports | D33: Team Sports | E33: Nolan-Snow | F33: 204.39 | G33: 281
A34: PROD32 | B34: Vitamin C Face Serum | C34: Beauty | D34: Skincare | E34: Griffin Ltd | F34: 283.83 | G34: 244
A35: PROD33 | B35: Modern Wall Clock | C35: Home | D35: Decor | E35: Weiss-Watson | F35: 179.77 | G35: 305
A36: PROD34 | B36: Gaming Mechanical Keyboard | C36: Electronics | D36: Computer | E36: Lucero LLC | F36: 419.28 | G36: 86
A37: PROD35 | B37: Bedroom Table Lamp | C37: Home | D37: Lighting | E37: Jones LLC | F37: 382.22 | G37: 329
A38: PROD36 | B38: Women's Summer Dress | C38: Clothing | D38: Tops | E38: Smith-Mills | F38: 223.43 | G38: 154
A39: PROD37 | B39: Men's Casual Sneakers | C39: Clothing | D39: Footwear | E39: Hogan-Lee | F39: 353.47 | G39: 214
A40: PROD38 | B40: Sports Water Hydration Pack | C40: Sports | D40: Outdoor | E40: Sims-Smith | F40: 135.61 | G40: 394
...

Sheet Store_Dim
A1: Store_ID | B1: Store_Name | C1: Region | D1: City | E1: Store_Type
A2: STORE0 | B2: Rivera-Warner | C2: East | D2: Washingtonfurt | E2: Flagship
A3: STORE1 | B3: Martinez, Adkins and Johnson | C3: North | D3: Danielmouth | E3: Flagship
A4: STORE2 | B4: Black-Horn | C4: South | D4: North Nancyview | E4: Outlet
A5: STORE3 | B5: Johnson-Wright | C5: North | D5: Hoodberg | E5: Outlet
A6: STORE4 | B6: Alexander Group | C6: South | D6: Port Sharon | E6: Online
A7: STORE5 | B7: Gray Ltd | C7: North | D7: New Michaelchester | E7: Outlet
A8: STORE6 | B8: Benson-Elliott | C8: East | D8: Port Josephberg | E8: Online
A9: STORE7 | B9: Martinez-Mullins | C9: South | D9: Williamsfurt | E9: Online
A10: STORE8 | B10: Bean, Jones and Park | C10: West | D10: Thompsonborough | E10: Online
A11: STORE9 | B11: Moore, Padilla and Butler | C11: South | D11: East Johnstad | E11: Flagship
A12: STORE10 | B12: Hill, Wagner and Ballard | C12: East | D12: East Davidville | E12: Online
... A21: STORE19 | B21: Mann-Austin | C21: East | D21: Vasquezborough | E21: Online

Sheet Sales_Fact
A1: Sales_ID | B1: Order_Date | C1: Customer_ID | D1: Product_ID | E1: Store_ID | F1: Quantity | G1: Unit_Price | H1: Discount | I1: Payment_Type | J1: Total_Amount
A2: SALE0 | B2: 45480 | C2: CUST1409 | D2: PROD97 | E2: STORE3 | F2: 1 | G2: 218.04 | H2: 0.09 | I2: Credit Card | J2: 198.4164
A3: SALE1 | B3: 45285 | C3: CUST1467 | D3: PROD74 | E3: STORE17 | F3: 3 | G3: 104.47 | H3: 0.27 | I3: PayPal | J3: 228.7893
A4: SALE2 | B4: 45446 | C4: CUST1056 | D4: PROD49 | E4: STORE8 | F4: 4 | G4: 914.05 | H4: 0.25 | I4: Credit Card | J4: 2742.15
A5: SALE3 | B5: 45259 | C5: CUST1346 | D5: PROD76 | E5: STORE8 | F5: 1 | G5: 921.51 | H5: 0.16 | I5: COD | J5: 774.0684
A6: SALE4 | B6: 45297 | C6: CUST1493 | D6: PROD59 | E6: STORE5 | F6: 3 | G6: 745.3 | H6: 0.18 | I6: Credit Card | J6: 1833.438
A7: SALE5 | B7: 45499 | C7: CUST1116 | D7: PROD15 | E7: STORE7 | F7: 3 | G7: 147.01 | H7: 0.19 | I7: COD | J7: 357.2343
A8: SALE6 | B8: 45850 | C8: CUST1016 | D8: PROD56 | E8: STORE4 | F8: 2 | G8: 785.31 | H8: 0.15 | I8: PayPal | J8: 1335.027
A9: SALE7 | B9: 45248 | C9: CUST1152 | D9: PROD70 | E9: STORE8 | F9: 4 | G9: 342.39 | H9: 0.23 | I9: PayPal | J9: 1054.5612
A10: SALE8 | B10: 45781 | C10: CUST1187 | D10: PROD99 | E10: STORE5 | G10: 448.25 | H10: 0.07 | I10: PayPal | J10: 1250.6175
A11: SALE9 | B11: 45869 | C11: CUST1464 | D11: PROD33 | E11: STORE0 | F11: 2 | G11: 873.17 | H11: 0.23 | I11: PayPal | J11: 1344.6818
A12: SALE10 | B12: 45335 | C12: CUST1065 | D12: PROD24 | E12: STORE14 | F12: 1 | G12: 278.63 | H12: 0.07 | I12: Credit Card | J12: 259.1259
A13: SALE11 | B13: 45801 | C13: CUST1320 | D13: PROD39 | E13: STORE1 | F13: 4 | G13: 286.92 | H13: 0.17 | I13: Credit Card | J13: 952.5744
A14: SALE12 | B14: 45528 | C14: CUST1237 | D14: PROD88 | E14: STORE4 | F14: 4 | G14: 644.58 | H14: 0.01 | I14: Credit Card | J14: 2552.5368
A15: SALE13 | B15: 45875 | C15: CUST1443 | D15: PROD34 | E15: STORE16 | F15: 2 | G15: 316.9 | H15: 0.3 | I15: PayPal | J15: 443.66
A16: SALE14 | B16: 45829 | C16: CUST1348 | D16: PROD24 | E16: STORE15 | F16: 4 | G16: 403.47 | H16: 0.29 | I16: PayPal | J16: 1145.8548
A17: SALE15 | B17: 45636 | C17: CUST1435 | D17: PROD36 | E17: STORE9 | G17: 871.34 | H17: 0.04 | I17: COD | J17: 2509.4592
A18: SALE16 | B18: 45913 | C18: CUST1276 | D18: PROD65 | E18: STORE19 | F18: 2 | G18: 451.98 | H18: 0.25 | I18: Credit Card | J18: 677.97
A19: SALE17 | B19: 45637 | C19: CUST1079 | D19: PROD27 | E19: STORE4 | F19: 2 | G19: 502.69 | H19: 0.23 | I19: Credit Card | J19: 774.1426
A20: SALE18 | B20: 45517 | C20: CUST1094 | D20: PROD39 | E20: STORE4 | F20: 2 | G20: 559.23 | H20: 0.25 | I20: COD | J20: 838.845
A21: SALE19 | B21: 45369 | C21: CUST1239 | D21: PROD60 | E21: STORE13 | F21: 4 | H21: 0.04 | I21: COD | J21: 1782.4512
A22: SALE20 | B22: 45843 | C22: CUST1144 | D22: PROD72 | E22: STORE17 | F22: 3 | G22: 986.04 | H22: 0.27 | I22: COD | J22: 2159.4276
A23: SALE21 | B23: 45447 | C23: CUST1396 | D23: PROD43 | E23: STORE18 | F23: 1 | G23: 589.56 | H23: 0.22 | I23: Credit Card | J23: 459.8568
A24: SALE22 | B24: 45394 | C24: CUST1476 | D24: PROD69 | E24: STORE10 | F24: 3 | G24: 979.42 | H24: 0.03 | I24: PayPal | J24: 2850.1122
A25: SALE23 | B25: 45466 | C25: CUST1368 | D25: PROD12 | E25: STORE8 | F25: 1 | G25: 719.28 | H25: 0.08 | I25: Credit Card | J25: 661.7376
A26: SALE24 | B26: 45908 | C26: CUST1186 | D26: PROD67 | E26: STORE6 | F26: 3 | G26: 77.6 | H26: 0.07 | I26: Credit Card | J26: 216.504
A27: SALE25 | B27: 45552 | C27: CUST1381 | D27: PROD5 | E27: STORE3 | F27: 4 | G27: 852.71 | H27: 0.14 | I27: PayPal | J27: 2933.3224
A28: SALE26 | B28: 45294 | C28: CUST1213 | D28: PROD98 | E28: STORE8 | F28: 4 | G28: 156.16 | I28: Credit Card | J28: 599.6544
A29: SALE27 | B29: 45710 | C29: CUST1200 | D29: PROD77 | E29: STORE8 | F29: 3 | G29: 815.49 | H29: 0.17 | I29: Credit Card | J29: 2030.5701
A30: SALE28 | B30: 45923 | C30: CUST1148 | D30: PROD13 | E30: STORE2 | F30: 2 | G30: 74.21 | H30: 0.11 | I30: PayPal | J30: 132.0938
A31: SALE29 | B31: 45302 | C31: CUST1348 | D31: PROD99 | E31: STORE3 | G31: 451.67 | H31: 0.15 | I31: Credit Card | J31: 1535.678
A32: SALE30 | B32: 45217 | C32: CUST1028 | D32: PROD5 | E32: STORE19 | F32: 1 | G32: 429.38 | H32: 0.13 | I32: PayPal | J32: 373.5606
A33: SALE31 | B33: 45593 | C33: CUST1412 | D33: PROD53 | E33: STORE12 | F33: 2 | G33: 148.96 | H33: 0.03 | I33: COD | J33: 288.9824
A34: SALE32 | B34: 45597 | C34: CUST1398 | D34: PROD75 | E34: STORE8 | F34: 4 | G34: 313.83 | H34: 0.08 | I34: Credit Card | J34: 1154.8944
A35: SALE33 | B35: 45620 | C35: CUST1453 | D35: PROD12 | E35: STORE6 | F35: 2 | G35: 717.31 | H35: 0.15 | I35: Credit Card | J35: 1219.427
A36: SALE34 | B36: 45215 | C36: CUST1344 | D36: PROD79 | E36: STORE1 | G36: 873.22 | H36: 0.18 | I36: Credit Card | J36: 2148.1212
A37: SALE35 | B37: 45878 | C37: CUST1218 | D37: PROD16 | E37: STORE3 | F37: 4 | G37: 109.36 | H37: 0.19 | I37: COD | J37: 354.3264
A38: SALE36 | B38: 45635 | C38: CUST1086 | D38: PROD5 | E38: STORE7 | F38: 3 | G38: 559.52 | H38: 0.16 | I38: PayPal | J38: 1409.9904
A39: SALE37 | B39: 45329 | C39: CUST1492 | D39: PROD10 | E39: STORE17 | F39: 3 | G39: 121.76 | H39: 0.27 | I39: PayPal | J39: 266.6544
A40: SALE38 | B40: 45378 | C40: CUST1189 | D40: PROD33 | E40: STORE13 | F40: 4 | G40: 735.32 | H40: 0.06 | I40: COD | J40: 2764.8032
...

Sheet Cleen customer data
A1: Customer_ID | B1: Name | C1: Column1 | D1: Age | E1: Gender | F1: State | G1: Country | H1: Loyality level | I1: Loyalty_Level
A2: CUST1000 | B2: sheena bonilla | C2: =PROPER(TRIM(B2)) -> Sheena Bonilla | D2: 55 | E2: Male | F2: North Carolina | G2: USA | H2: =IF(ISBLANK(Table2[[#This Row],[Loyalty_Level]]),"Unknown",I2) -> Unknown
A3: CUST1001 | B3: Eugene Nelson | C3: =PROPER(TRIM(B3)) -> Eugene Nelson | D3: 26 | E3: Female | F3: North Dakota | G3: USA | H3: =IF(ISBLANK(Table2[[#This Row],[Loyalty_Level]]),"Unknown",I3) -> Platinum | I3: Platinum
A4: CUST1002 | B4: dr. Benjamin Price | C4: =PROPER(TRIM(B4)) -> Dr. Benjamin Price | D4: 29 | E4: Female | F4: Alabama | G4: USA | H4: =IF(ISBLANK(Table2[[#This Row],[Loyalty_Level]]),"Unknown",I4) -> Platinum | I4: Platinum
A5: CUST1003 | B5: jeremy harris | C5: =PROPER(TRIM(B5)) -> Jeremy Harris | D5: 59 | E5: Female | F5: Ohio | G5: USA | H5: =IF(ISBLANK(Table2[[#This Row],[Loyalty_Level]]),"Unknown",I5) -> Bronze | I5: Bronze
A6: CUST1004 | B6: Caroline Collins | C6: =PROPER(TRIM(B6)) -> Caroline Collins | D6: 64 | E6: Female | F6: California | G6: USA | H6: =IF(ISBLANK(Table2[[#This Row],[Loyalty_Level]]),"Unknown",I6) -> Silver | I6: Silver
A7: CUST1005 | B7: Christine Vaughn | C7: =PROPER(TRIM(B7)) -> Christine Vaughn | D7: 24 | E7: Male | F7: Oregon | G7: USA | H7: =IF(ISBLANK(Table2[[#This Row],[Loyalty_Level]]),"Unknown",I7) -> Bronze | I7: Bronze
A8: CUST1006 | B8: Amber Jackson | C8: =PROPER(TRIM(B8)) -> Amber Jackson | D8: 29 | E8: Female | F8: South Dakota | G8: USA | H8: =IF(ISBLANK(Table2[[#This Row],[Loyalty_Level]]),"Unknown",I8) -> Platinum | I8: Platinum
A9: CUST1007 | B9: Daniel Boyd | C9: =PROPER(TRIM(B9)) -> Daniel Boyd | D9: 29 | E9: Female | F9: West Virginia | G9: USA | H9: =IF(ISBLANK(Table2[[#This Row],[Loyalty_Level]]),"Unknown",I9) -> Bronze | I9: Bronze
A10: CUST1008 | B10: Melissa Howard | C10: =PROPER(TRIM(B10)) -> Melissa Howard | D10: 53 | E10: Female | F10: New Hampshire | G10: USA | H10: =IF(ISBLANK(Table2[[#This Row],[Loyalty_Level]]),"Unknown",I10) -> Gold | I10: Gold
A11: CUST1009 | B11: Ms. Maria Leach | C11: =PROPER(TRIM(B11)) -> Ms. Maria Leach | D11: 64 | E11: Male | F11: Pennsylvania | G11: USA | H11: =IF(ISBLANK(Table2[[#This Row],[Loyalty_Level]]),"Unknown",I11) -> Platinum | I11: Platinum
A12: CUST1010 | B12: Dominic Page | C12: =PROPER(TRIM(B12)) -> Dominic Page | D12: 53 | E12: Male | F12: Pennsylvania | G12: USA | H12: =IF(ISBLANK(Table2[[#This Row],[Loyalty_Level]]),"Unknown",I12) -> Bronze | I12: Bronze
A13: CUST1011 | B13: Brian Lopez | C13: =PROPER(TRIM(B13)) -> Brian Lopez | D13: 28 | E13: Female | F13: New York | G13: USA | H13: =IF(ISBLANK(Table2[[#This Row],[Loyalty_Level]]),"Unknown",I13) -> Gold | I13: Gold
A14: CUST1012 | B14: Kenneth Lambert | C14: =PROPER(TRIM(B14)) -> Kenneth Lambert | D14: 55 | E14: Female | F14: Kansas | G14: USA | H14: =IF(ISBLANK(Table2[[#This Row],[Loyalty_Level]]),"Unknown",I14) -> Platinum | I14: Platinum
... A19: CUST1017 | B19: Adam Cruz | C19: =PROPER(TRIM(B19)) -> Adam Cruz | D19: 60 | E19: Female | F19: Georgia | G19: USA | H19: =IF(ISBLANK(Table2[[#This Row],[Loyalty_Level]]),"Unknown",I19) -> Platinum | I19: Platinum
A20: CUST1018 | B20: Rhonda Moss | C20: =PROPER(TRIM(B20)) -> Rhonda Moss | D20: 43 | E20: Male | F20: Kansas | G20: USA | H20: =IF(ISBLANK(Table2[[#This Row],[Loyalty_Level]]),"Unknown",I20) -> Unknown
A21: CUST1019 | B21: Michael Torres | C21: =PROPER(TRIM(B21)) -> Michael Torres | D21: 46 | E21: Female | F21: New Jersey | G21: USA | H21: =IF(ISBLANK(Table2[[#This Row],[Loyalty_Level]]),"Unknown",I21) -> Platinum | I21: Platinum
A22: CUST1020 | B22: Bridget Allen | C22: =PROPER(TRIM(B22)) -> Bridget Allen | D22: 59 | E22: Male | F22: Delaware | G22: USA | H22: =IF(ISBLANK(Table2[[#This Row],[Loyalty_Level]]),"Unknown",I22) -> Silver | I22: Silver
A23: CUST1021 | B23: Jeff Martinez | C23: =PROPER(TRIM(B23)) -> Jeff Martinez | D23: 36 | E23: Female | F23: Oklahoma | G23: USA | H23: =IF(ISBLANK(Table2[[#This Row],[Loyalty_Level]]),"Unknown",I23) -> Gold | I23: Gold
A24: CUST1022 | B24: paul fox | C24: =PROPER(TRIM(B24)) -> Paul Fox | D24: 33 | E24: Female | F24: Hawaii | G24: USA | H24: =IF(ISBLANK(Table2[[#This Row],[Loyalty_Level]]),"Unknown",I24) -> Silver | I24: Silver
A25: CUST1023 | B25: Jonathan Steele | C25: =PROPER(TRIM(B25)) -> Jonathan Steele | D25: 52 | E25: Female | F25: Oregon | G25: USA | H25: =IF(ISBLANK(Table2[[#This Row],[Loyalty_Level]]),"Unknown",I25) -> Silver | I25: Silver
A26: CUST1024 | B26: Heather Collins | C26: =PROPER(TRIM(B26)) -> Heather Collins | D26: 40 | E26: Male | F26: Idaho | G26: USA | H26: =IF(ISBLANK(Table2[[#This Row],[Loyalty_Level]]),"Unknown",I26) -> Platinum | I26: Platinum
A27: CUST1025 | B27: Diana Taylor | C27: =PROPER(TRIM(B27)) -> Diana Taylor | D27: 59 | E27: Female | F27: California | G27: USA | H27: =IF(ISBLANK(Table2[[#This Row],[Loyalty_Level]]),"Unknown",I27) -> Bronze | I27: Bronze
A28: CUST1026 | B28: Amber Carlson | C28: =PROPER(TRIM(B28)) -> Amber Carlson | D28: 18 | E28: Female | F28: Missouri | G28: USA | H28: =IF(ISBLANK(Table2[[#This Row],[Loyalty_Level]]),"Unknown",I28) -> Gold | I28: Gold
A29: CUST1027 | B29: Leslie Johnson | C29: =PROPER(TRIM(B29)) -> Leslie Johnson | D29: 31 | E29: Male | F29: Utah | G29: USA | H29: =IF(ISBLANK(Table2[[#This Row],[Loyalty_Level]]),"Unknown",I29) -> Unknown
A30: CUST1028 | B30: Joshua Ryan | C30: =PROPER(TRIM(B30)) -> Joshua Ryan | D30: 27 | E30: Female | F30: New Jersey | G30: USA | H30: =IF(ISBLANK(Table2[[#This Row],[Loyalty_Level]]),"Unknown",I30) -> Platinum | I30: Platinum
A31: CUST1029 | B31: David Arnold | C31: =PROPER(TRIM(B31)) -> David Arnold | D31: 54 | E31: Female | F31: California | G31: USA | H31: =IF(ISBLANK(Table2[[#This Row],[Loyalty_Level]]),"Unknown",I31) -> Silver | I31: Silver
A32: CUST1030 | B32: Jessica Acevedo | C32: =PROPER(TRIM(B32)) -> Jessica Acevedo | D32: 64 | E32: Female | F32: Pennsylvania | G32: USA | H32: =IF(ISBLANK(Table2[[#This Row],[Loyalty_Level]]),"Unknown",I32) -> Bronze | I32: Bronze
A33: CUST1031 | B33: Sarah Vance | C33: =PROPER(TRIM(B33)) -> Sarah Vance | D33: 41 | E33: Male | F33: Oregon | G33: USA | H33: =IF(ISBLANK(Table2[[#This Row],[Loyalty_Level]]),"Unknown",I33) -> Silver | I33: Silver
A34: CUST1032 | B34: Mike Jennings | C34: =PROPER(TRIM(B34)) -> Mike Jennings | D34: 48 | E34: Female | F34: Arizona | G34: USA | H34: =IF(ISBLANK(Table2[[#This Row],[Loyalty_Level]]),"Unknown",I34) -> Gold | I34: Gold
A35: CUST1033 | B35: Robert Jones DDS | C35: =PROPER(TRIM(B35)) -> Robert Jones Dds | D35: 25 | E35: Male | F35: Oklahoma | G35: USA | H35: =IF(ISBLANK(Table2[[#This Row],[Loyalty_Level]]),"Unknown",I35) -> Platinum | I35: Platinum
A36: CUST1034 | B36: Christopher Olson | C36: =PROPER(TRIM(B36)) -> Christopher Olson | D36: 27 | E36: Female | F36: Maryland | G36: USA | H36: =IF(ISBLANK(Table2[[#This Row],[Loyalty_Level]]),"Unknown",I36) -> Platinum | I36: Platinum
A37: CUST1035 | B37: Rachel Myers | C37: =PROPER(TRIM(B37)) -> Rachel Myers | D37: 52 | E37: Male | F37: North Dakota | G37: USA | H37: =IF(ISBLANK(Table2[[#This Row],[Loyalty_Level]]),"Unknown",I37) -> Silver | I37: Silver
A38: CUST1036 | B38: Thomas Phillips | C38: =PROPER(TRIM(B38)) -> Thomas Phillips | D38: 20 | E38: Female | F38: Georgia | G38: USA | H38: =IF(ISBLANK(Table2[[#This Row],[Loyalty_Level]]),"Unknown",I38) -> Gold | I38: Gold
A39: CUST1037 | B39: Christopher Carter | C39: =PROPER(TRIM(B39)) -> Christopher Carter | D39: 27 | E39: Female | F39: South Dakota | G39: USA | H39: =IF(ISBLANK(Table2[[#This Row],[Loyalty_Level]]),"Unknown",I39) -> Unknown
A40: CUST1038 | B40: Deanna Simpson | C40: =PROPER(TRIM(B40)) -> Deanna Simpson | D40: 35 | E40: Female | F40: North Dakota | G40: USA | H40: =IF(ISBLANK(Table2[[#This Row],[Loyalty_Level]]),"Unknown",I40) -> Bronze | I40: Bronze
A41: CUST1039 | B41: Tonya Reynolds | C41: =PROPER(TRIM(B41)) -> Tonya Reynolds | D41: 55 | E41: Female | F41: Michigan | G41: USA | H41: =IF(ISBLANK(Table2[[#This Row],[Loyalty_Level]]),"Unknown",I41) -> Gold | I41: Gold
A42: CUST1040 | B42: Eric Vega | C42: =PROPER(TRIM(B42)) -> Eric Vega | D42: 50 | E42: Male | F42: Kansas | G42: USA | H42: =IF(ISBLANK(Table2[[#This Row],[Loyalty_Level]]),"Unknown",I42) -> Gold | I42: Gold
A43: CUST1041 | B43: James Gibbs | C43: =PROPER(TRIM(B43)) -> James Gibbs | D43: 21 | E43: Male | F43: Alaska | G43: USA | H43: =IF(ISBLANK(Table2[[#This Row],[Loyalty_Level]]),"Unknown",I43) -> Platinum | I43: Platinum
A44: CUST1042 | B44: William Martin | C44: =PROPER(TRIM(B44)) -> William Martin | D44: 19 | E44: Male | F44: Connecticut | G44: USA | H44: =IF(ISBLANK(Table2[[#This Row],[Loyalty_Level]]),"Unknown",I44) -> Platinum | I44: Platinum
...

Sheet customer data final
A1: Customer_ID | B1: Name | C1: Age | D1: Gender | E1: State | F1: Country | G1: Loyalty_Level
A2: CUST1000 | B2: Sheena Bonilla | C2: 55 | D2: Male | E2: North Carolina | F2: USA | G2: Unknown
A3: CUST1001 | B3: Eugene Nelson | C3: 26 | D3: Female | E3: North Dakota | F3: USA | G3: Platinum
A4: CUST1002 | B4: Dr. Benjamin Price | C4: 29 | D4: Female | E4: Alabama | F4: USA | G4: Platinum
A5: CUST1003 | B5: Jeremy Harris | C5: 59 | D5: Female | E5: Ohio | F5: USA | G5: Bronze
A6: CUST1004 | B6: Caroline Collins | C6: 64 | D6: Female | E6: California | F6: USA | G6: Silver
A7: CUST1005 | B7: Christine Vaughn | C7: 24 | D7: Male | E7: Oregon | F7: USA | G7: Bronze
A8: CUST1006 | B8: Amber Jackson | C8: 29 | D8: Female | E8: South Dakota | F8: USA | G8: Platinum
A9: CUST1007 | B9: Daniel Boyd | C9: 29 | D9: Female | E9: West Virginia | F9: USA | G9: Bronze
A10: CUST1008 | B10: Melissa Howard | C10: 53 | D10: Female | E10: New Hampshire | F10: USA | G10: Gold
A11: CUST1009 | B11: Ms. Maria Leach | C11: 64 | D11: Male | E11: Pennsylvania | F11: USA | G11: Platinum
A12: CUST1010 | B12: Dominic Page | C12: 53 | D12: Male | E12: Pennsylvania | F12: USA | G12: Bronze
A13: CUST1011 | B13: Brian Lopez | C13: 28 | D13: Female | E13: New York | F13: USA | G13: Gold
... A501: C-1499 | B501: Philip Pennington | C501: 27 | D501: Female | E501: Oregon | F501: USA | G501: Platinum

Sheet Clean Product_Dim (2)
A1: Product_ID | B1: Product_Name | C1: Category | D1: Brand | E1: Cost | F1: Cost2 | G1: Stocks | H1: Stock
A2: PROD0 | B2: Brother Laser Printer | C2: Electronics | D2: Hunt Inc | E2: =IF(ISBLANK(Table3[[#This Row],[Cost2]]),"Not Found",F2) -> 112.42 | F2: 112.42 | G2: =IF(ISBLANK(Table3[[#This Row],[Cost2]]),"0",F2) -> 112.42 | H2: 416
A3: PROD1 | B3: Men's Graphic T-Shirt | C3: Clothing | D3: Terry-Moore | E3: =IF(ISBLANK(Table3[[#This Row],[Cost2]]),"Not Found",F3) -> 342.56 | F3: 342.56 | G3: =IF(ISBLANK(Table3[[#This Row],[Stock]]),"0",H3) -> 181 | H3: 181
A4: PROD2 | B4: Women's Casual Hoodie | C4: Clothing | D4: Sims Inc | E4: =IF(ISBLANK(Table3[[#This Row],[Cost2]]),"Not Found",F4) -> Not Found | G4: =IF(ISBLANK(Table3[[#This Row],[Stock]]),"0",H4) -> 352 | H4: 352
A5: P-3 | B5: Men's Running Jacket | C5: Clothing | D5: Pineda Ltd | E5: =IF(ISBLANK(Table3[[#This Row],[Cost2]]),"Not Found",F5) -> 364.67 | F5: 364.67 | G5: =IF(ISBLANK(Table3[[#This Row],[Stock]]),"0",H5) -> 452 | H5: 452
A6: PROD4 | B6: Women's Yoga Pants | C6: Clothing | D6: Gonzales-Davis | E6: =IF(ISBLANK(Table3[[#This Row],[Cost2]]),"Not Found",F6) -> 306.46 | F6: 306.46 | G6: =IF(ISBLANK(Table3[[#This Row],[Stock]]),"0",H6) -> 487 | H6: 487
A7: PROD5 | B7: Men's Leather Belt | C7: Clothing | D7: Baldwin, Garza and Gonzalez | E7: =IF(ISBLANK(Table3[[#This Row],[Cost2]]),"Not Found",F7) -> 261 | F7: 261 | G7: =IF(ISBLANK(Table3[[#This Row],[Stock]]),"0",H7) -> 59 | H7: 59
A8: PROD6 | B8: Herbal Face Moisturizer | C8: Beauty | D8: Davidson PLC | E8: =IF(ISBLANK(Table3[[#This Row],[Cost2]]),"Not Found",F8) -> 312.8 | F8: 312.8 | G8: =IF(ISBLANK(Table3[[#This Row],[Stock]]),"0",H8) -> 350 | H8: 350
A9: PROD7 | B9: LED Table Lamp | C9: Home | D9: Harrell LLC | E9: =IF(ISBLANK(Table3[[#This Row],[Cost2]]),"Not Found",F9) -> 218.86 | F9: 218.86 | G9: =IF(ISBLANK(Table3[[#This Row],[Stock]]),"0",H9) -> 170 | H9: 170
A10: PROD8 | B10: Wireless Bluetooth Earbuds | C10: Electronics | D10: Perez-Johnston | E10: =IF(ISBLANK(Table3[[#This Row],[Cost2]]),"Not Found",F10) -> 439.07 | F10: 439.07 | G10: =IF(ISBLANK(Table3[[#This Row],[Stock]]),"0",H10) -> 142 | H10: 142
A11: PROD9 | B11: Adjustable Dumbbell Set | C11: Sports | D11: Hill PLC | E11: =IF(ISBLANK(Table3[[#This Row],[Cost2]]),"Not Found",F11) -> 495.72 | F11: 495.72 | G11: =IF(ISBLANK(Table3[[#This Row],[Stock]]),"0",H11) -> 323 | H11: 323
A12: PROD10 | B12: Ceramic Kitchen Bowl Set | C12: Home | D12: Hamilton Group | E12: =IF(ISBLANK(Table3[[#This Row],[Cost2]]),"Not Found",F12) -> 298.86 | F12: 298.86 | G12: =IF(ISBLANK(Table3[[#This Row],[Stock]]),"0",H12) -> 308 | H12: 308
A13: PROD11 | B13: HD Smart TV Stick | C13: Electronics | D13: Gibson, Hobbs and Weaver | E13: =IF(ISBLANK(Table3[[#This Row],[Cost2]]),"Not Found",F13) -> 449.4 | F13: 449.4 | G13: =IF(ISBLANK(Table3[[#This Row],[Stock]]),"0",H13) -> 0
A14: PROD12 | B14: Hair Strengthening Shampoo | C14: Beauty | D14: Rice LLC | E14: =IF(ISBLANK(Table3[[#This Row],[Cost2]]),"Not Found",F14) -> 115.82 | F14: 115.82 | G14: =IF(ISBLANK(Table3[[#This Row],[Stock]]),"0",H14) -> 460 | H14: 460
A15: PROD13 | B15: USB-C Fast Charger | C15: Electronics | D15: Dawson-Perkins | E15: =IF(ISBLANK(Table3[[#This Row],[Cost2]]),"Not Found",F15) -> 242.23 | F15: 242.23 | G15: =IF(ISBLANK(Table3[[#This Row],[Stock]]),"0",H15) -> 453 | H15: 453
A16: PROD14 | B16: Decorative Wall Mirror | C16: Home | D16: Luna, Anderson and Bowman | E16: =IF(ISBLANK(Table3[[#This Row],[Cost2]]),"Not Found",F16) -> 48.01 | F16: 48.01 | G16: =IF(ISBLANK(Table3[[#This Row],[Stock]]),"0",H16) -> 439 | H16: 439
A17: PROD15 | B17: 4K Home Projector | C17: Electronics | D17: Thomas LLC | E17: =IF(ISBLANK(Table3[[#This Row],[Cost2]]),"Not Found",F17) -> 465.34 | F17: 465.34 | G17: =IF(ISBLANK(Table3[[#This Row],[Stock]]),"0",H17) -> 301 | H17: 301
A18: P-16 | B18: Beard Grooming Kit | C18: Beauty | D18: Erickson-Green | E18: =IF(ISBLANK(Table3[[#This Row],[Cost2]]),"Not Found",F18) -> 337.42 | F18: 337.42 | G18: =IF(ISBLANK(Table3[[#This Row],[Stock]]),"0",H18) -> 256 | H18: 256
A19: PROD17 | B19: Soccer Training Cone Set | C19: Sports | D19: Ford, Murphy and Wilson | E19: =IF(ISBLANK(Table3[[#This Row],[Cost2]]),"Not Found",F19) -> 144.53 | F19: 144.53 | G19: =IF(ISBLANK(Table3[[#This Row],[Stock]]),"0",H19) -> 367 | H19: 367
A20: PROD18 | B20: Women's Denim Jeans | C20: Clothing | D20: Guerra-Hendrix | E20: =IF(ISBLANK(Table3[[#This Row],[Cost2]]),"Not Found",F20) -> Not Found | G20: =IF(ISBLANK(Table3[[#This Row],[Stock]]),"0",H20) -> 343 | H20: 343
A21: PROD19 | B21: Knee Support Brace | C21: Sports | D21: May-Reese | E21: =IF(ISBLANK(Table3[[#This Row],[Cost2]]),"Not Found",F21) -> 21.34 | F21: 21.34 | G21: =IF(ISBLANK(Table3[[#This Row],[Stock]]),"0",H21) -> 65 | H21: 65
A22: PROD20 | B22: Outdoor Sports Water Bottle | C22: Sports | D22: Soto-Ellis | E22: =IF(ISBLANK(Table3[[#This Row],[Cost2]]),"Not Found",F22) -> 131.51 | F22: 131.51 | G22: =IF(ISBLANK(Table3[[#This Row],[Stock]]),"0",H22) -> 0
A23: PROD21 | B23: Multi-Purpose Storage Box | C23: Home | D23: Gardner-Montes | E23: =IF(ISBLANK(Table3[[#This Row],[Cost2]]),"Not Found",F23) -> 123.46 | F23: 123.46 | G23: =IF(ISBLANK(Table3[[#This Row],[Stock]]),"0",H23) -> 76 | H23: 76
A24: PROD22 | B24: Carbon Fiber Tennis Racket | C24: Sports | D24: Flores, Pineda and Rodriguez | E24: =IF(ISBLANK(Table3[[#This Row],[Cost2]]),"Not Found",F24) -> 484.62 | F24: 484.62 | G24: =IF(ISBLANK(Table3[[#This Row],[Stock]]),"0",H24) -> 432 | H24: 432
A25: PROD23 | B25: Men's Formal Shirt | C25: Clothing | D25: Moon, Mora and Santos | E25: =IF(ISBLANK(Table3[[#This Row],[Cost2]]),"Not Found",F25) -> Not Found | G25: =IF(ISBLANK(Table3[[#This Row],[Stock]]),"0",H25) -> 360 | H25: 360
A26: PROD24 | B26: Foldable Camping Chair | C26: Sports | D26: Cook Ltd | E26: =IF(ISBLANK(Table3[[#This Row],[Cost2]]),"Not Found",F26) -> 166.06 | F26: 166.06 | G26: =IF(ISBLANK(Table3[[#This Row],[Stock]]),"0",H26) -> 340 | H26: 340
A27: PROD25 | B27: Women's Scarf Set | C27: Clothing | D27: Brown and Sons | E27: =IF(ISBLANK(Table3[[#This Row],[Cost2]]),"Not Found",F27) -> 174.02 | F27: 174.02 | G27: =IF(ISBLANK(Table3[[#This Row],[Stock]]),"0",H27) -> 268 | H27: 268
A28: PROD26 | B28: Wireless Bluetooth Speaker | C28: Electronics | D28: Reed-Schmidt | E28: =IF(ISBLANK(Table3[[#This Row],[Cost2]]),"Not Found",F28) -> 322.41 | F28: 322.41 | G28: =IF(ISBLANK(Table3[[#This Row],[Stock]]),"0",H28) -> 213 | H28: 213
A29: PROD27 | B29: Decorative Floor Vase | C29: Home | D29: Khan, Jones and Paul | E29: =IF(ISBLANK(Table3[[#This Row],[Cost2]]),"Not Found",F29) -> Not Found | G29: =IF(ISBLANK(Table3[[#This Row],[Stock]]),"0",H29) -> 378 | H29: 378
A30: PROD28 | B30: Sports Stopwatch Timer | C30: Sports | D30: Burns-Hansen | E30: =IF(ISBLANK(Table3[[#This Row],[Cost2]]),"Not Found",F30) -> 38.76 | F30: 38.76 | G30: =IF(ISBLANK(Table3[[#This Row],[Stock]]),"0",H30) -> 137 | H30: 137
A31: PROD29 | B31: Fabric Sofa Throw Blanket | C31: Home | D31: Hoffman Group | E31: =IF(ISBLANK(Table3[[#This Row],[Cost2]]),"Not Found",F31) -> 218.48 | F31: 218.48 | G31: =IF(ISBLANK(Table3[[#This Row],[Stock]]),"0",H31) -> 276 | H31: 276
A32: PROD30 | B32: Stainless Steel Cutlery Set | C32: Home | D32: Stevens, Fernandez and Martin | E32: =IF(ISBLANK(Table3[[#This Row],[Cost2]]),"Not Found",F32) -> 19.52 | F32: 19.52 | G32: =IF(ISBLANK(Table3[[#This Row],[Stock]]),"0",H32) -> 57 | H32: 57
A33: PROD31 | B33: Basketball | C33: Sports | D33: Nolan-Snow | E33: =IF(ISBLANK(Table3[[#This Row],[Cost2]]),"Not Found",F33) -> 204.39 | F33: 204.39 | G33: =IF(ISBLANK(Table3[[#This Row],[Stock]]),"0",H33) -> 281 | H33: 281
A34: PROD32 | B34: Vitamin C Face Serum | C34: Beauty | D34: Griffin Ltd | E34: =IF(ISBLANK(Table3[[#This Row],[Cost2]]),"Not Found",F34) -> 283.83 | F34: 283.83 | G34: =IF(ISBLANK(Table3[[#This Row],[Stock]]),"0",H34) -> 244 | H34: 244
A35: PROD33 | B35: Modern Wall Clock | C35: Home | D35: Weiss-Watson | E35: =IF(ISBLANK(Table3[[#This Row],[Cost2]]),"Not Found",F35) -> 179.77 | F35: 179.77 | G35: =IF(ISBLANK(Table3[[#This Row],[Stock]]),"0",H35) -> 305 | H35: 305
A36: PROD34 | B36: Gaming Mechanical Keyboard | C36: Electronics | D36: Lucero LLC | E36: =IF(ISBLANK(Table3[[#This Row],[Cost2]]),"Not Found",F36) -> 419.28 | F36: 419.28 | G36: =IF(ISBLANK(Table3[[#This Row],[Stock]]),"0",H36) -> 86 | H36: 86
A37: PROD35 | B37: Bedroom Table Lamp | C37: Home | D37: Jones LLC | E37: =IF(ISBLANK(Table3[[#This Row],[Cost2]]),"Not Found",F37) -> 382.22 | F37: 382.22 | G37: =IF(ISBLANK(Table3[[#This Row],[Stock]]),"0",H37) -> 329 | H37: 329
A38: PROD36 | B38: Women's Summer Dress | C38: Clothing | D38: Smith-Mills | E38: =IF(ISBLANK(Table3[[#This Row],[Cost2]]),"Not Found",F38) -> 223.43 | F38: 223.43 | G38: =IF(ISBLANK(Table3[[#This Row],[Stock]]),"0",H38) -> 154 | H38: 154
A39: PROD37 | B39: Men's Casual Sneakers | C39: Clothing | D39: Hogan-Lee | E39: =IF(ISBLANK(Table3[[#This Row],[Cost2]]),"Not Found",F39) -> 353.47 | F39: 353.47 | G39: =IF(ISBLANK(Table3[[#This Row],[Stock]]),"0",H39) -> 214 | H39: 214
A40: PROD38 | B40: Sports Water Hydration Pack | C40: Sports | D40: Sims-Smith | E40: =IF(ISBLANK(Table3[[#This Row],[Cost2]]),"Not Found",F40) -> 135.61 | F40: 135.61 | G40: =IF(ISBLANK(Table3[[#This Row],[Stock]]),"0",H40) -> 394 | H40: 394
...

Sheet clean product final
A1: Product_ID | B1: Product_Name | C1: Category | D1: Brand | E1: Cost | F1: Stock
A2: PROD0 | B2: Brother Laser Printer | C2: Electronics | D2: Hunt Inc | E2: 112.42 | F2: 416
A3: PROD1 | B3: Men's Graphic T-Shirt | C3: Clothing | D3: Terry-Moore | E3: 342.56 | F3: 181
A4: PROD2 | B4: Women's Casual Hoodie | C4: Clothing | D4: Sims Inc | E4: Not Found | F4: 352
A5: PROD3 | B5: Men's Running Jacket | C5: Clothing | D5: Pineda Ltd | E5: 364.67 | F5: 452
A6: PROD4 | B6: Women's Yoga Pants | C6: Clothing | D6: Gonzales-Davis | E6: 306.46 | F6: 487
A7: PROD5 | B7: Men's Leather Belt | C7: Clothing | D7: Baldwin, Garza and Gonzalez | E7: 261 | F7: 59
A8: PROD6 | B8: Herbal Face Moisturizer | C8: Beauty | D8: Davidson PLC | E8: 312.8 | F8: 350
A9: PROD7 | B9: LED Table Lamp | C9: Home | D9: Harrell LLC | E9: 218.86 | F9: 170
A10: PROD8 | B10: Wireless Bluetooth Earbuds | C10: Electronics | D10: Perez-Johnston | E10: 439.07 | F10: 142
A11: PROD9 | B11: Adjustable Dumbbell Set | C11: Sports | D11: Hill PLC | E11: 495.72 | F11: 323
A12: PROD10 | B12: Ceramic Kitchen Bowl Set | C12: Home | D12: Hamilton Group | E12: 298.86 | F12: 308
A13: PROD11 | B13: HD Smart TV Stick | C13: Electronics | D13: Gibson, Hobbs and Weaver | E13: 449.4 | F13: 0
A14: PROD12 | B14: Hair Strengthening Shampoo | C14: Beauty | D14: Rice LLC | E14: 115.82 | F14: 460
A15: PROD13 | B15: USB-C Fast Charger | C15: Electronics | D15: Dawson-Perkins | E15: 242.23 | F15: 453
A16: PROD14 | B16: Decorative Wall Mirror | C16: Home | D16: Luna, Anderson and Bowman | E16: 48.01 | F16: 439
... A19: PROD17 | B19: Soccer Training Cone Set | C19: Sports | D19: Ford, Murphy and Wilson | E19: 144.53 | F19: 367
A20: PROD18 | B20: Women's Denim Jeans | C20: Clothing | D20: Guerra-Hendrix | E20: Not Found | F20: 343
A21: PROD19 | B21: Knee Support Brace | C21: Sports | D21: May-Reese | E21: 21.34 | F21: 65
A22: PROD20 | B22: Outdoor Sports Water Bottle | C22: Sports | D22: Soto-Ellis | E22: 131.51 | F22: 0
A23: PROD21 | B23: Multi-Purpose Storage Box | C23: Home | D23: Gardner-Montes | E23: 123.46 | F23: 76
A24: PROD22 | B24: Carbon Fiber Tennis Racket | C24: Sports | D24: Flores, Pineda and Rodriguez | E24: 484.62 | F24: 432
A25: PROD23 | B25: Men's Formal Shirt | C25: Clothing | D25: Moon, Mora and Santos | E25: 242.965 | F25: 360
A26: PROD24 | B26: Foldable Camping Chair | C26: Sports | D26: Cook Ltd | E26: 166.06 | F26: 340
A27: PROD25 | B27: Women's Scarf Set | C27: Clothing | D27: Brown and Sons | E27: 174.02 | F27: 268
A28: PROD26 | B28: Wireless Bluetooth Speaker | C28: Electronics | D28: Reed-Schmidt | E28: 322.41 | F28: 213
A29: PROD27 | B29: Decorative Floor Vase | C29: Home | D29: Khan, Jones and Paul | E29: Not Found | F29: 378
A30: PROD28 | B30: Sports Stopwatch Timer | C30: Sports | D30: Burns-Hansen | E30: 38.76 | F30: 137
A31: PROD29 | B31: Fabric Sofa Throw Blanket | C31: Home | D31: Hoffman Group | E31: 218.48 | F31: 276
A32: PROD30 | B32: Stainless Steel Cutlery Set | C32: Home | D32: Stevens, Fernandez and Martin | E32: 19.52 | F32: 57
A33: PROD31 | B33: Basketball | C33: Sports | D33: Nolan-Snow | E33: 204.39 | F33: 281
A34: PROD32 | B34: Vitamin C Face Serum | C34: Beauty | D34: Griffin Ltd | E34: 283.83 | F34: 244
A35: PROD33 | B35: Modern Wall Clock | C35: Home | D35: Weiss-Watson | E35: 179.77 | F35: 305
A36: PROD34 | B36: Gaming Mechanical Keyboard | C36: Electronics | D36: Lucero LLC | E36: 419.28 | F36: 86
A37: PROD35 | B37: Bedroom Table Lamp | C37: Home | D37: Jones LLC | E37: 382.22 | F37: 329
A38: PROD36 | B38: Women's Summer Dress | C38: Clothing | D38: Smith-Mills | E38: 223.43 | F38: 154
A39: PROD37 | B39: Men's Casual Sneakers | C39: Clothing | D39: Hogan-Lee | E39: 353.47 | F39: 214
A40: PROD38 | B40: Sports Water Hydration Pack | C40: Sports | D40: Sims-Smith | E40: 135.61 | F40: 394
A41: PROD39 | B41: Portable Power Bank | C41: Electronics | D41: Cummings and Sons | E41: 326.06 | F41: 301
... A48: PROD46 | B48: Men's Winter Jacket | C48: Clothing | D48: Kelly, Smith and Perez | E48: 167.34 | F48: 296
...

Sheet Clean Store_Dim (2)
A1: Store_ID | B1: Store_Name | C1: Region | D1: City | E1: Store_Type
A2: STORE0 | B2: Rivera-Warner | C2: East | D2: Washingtonfurt | E2: Flagship
A3: STORE1 | B3: Martinez, Adkins and Johnson | C3: North | D3: Danielmouth | E3: Flagship
A4: STORE2 | B4: Black-Horn | C4: South | D4: North Nancyview | E4: Outlet
A5: STORE3 | B5: Johnson-Wright | C5: North | D5: Hoodberg | E5: Outlet
A6: STORE4 | B6: Alexander Group | C6: South | D6: Port Sharon | E6: Online
A7: STORE5 | B7: Gray Ltd | C7: North | D7: New Michaelchester | E7: Outlet
A8: STORE6 | B8: Benson-Elliott | C8: East | D8: Port Josephberg | E8: Online
A9: STORE7 | B9: Martinez-Mullins | C9: South | D9: Williamsfurt | E9: Online
A10: STORE8 | B10: Bean, Jones and Park | C10: West | D10: Thompsonborough | E10: Online
A11: STORE9 | B11: Moore, Padilla and Butler | C11: South | D11: East Johnstad | E11: Flagship
A12: STORE10 | B12: Hill, Wagner and Ballard | C12: East | D12: East Davidville | E12: Online
... A21: STORE19 | B21: Mann-Austin | C21: East | D21: Vasquezborough | E21: Online

Sheet Clean Sales_Fact (2)
A1: Sales_ID | B1: Order_Date | C1: Customer_ID | D1: Product_ID | E1: Store_ID | F1: Quantity | G1: Unit_Price | H1: Discount | I1: Payment_Type | J1: Total_Amount
A2: SALE0 | B2: 45480 | C2: CUST1409 | D2: PROD97 | E2: STORE3 | F2: 1 | G2: 218.04 | H2: 0.09 | I2: Credit Card | J2: 198.4164
A3: SALE1 | B3: 45285 | C3: CUST1467 | D3: PROD74 | E3: STORE17 | F3: 3 | G3: 104.47 | H3: 0.27 | I3: PayPal | J3: 228.7893
A4: SALE2 | B4: 45446 | C4: CUST1056 | D4: PROD49 | E4: STORE8 | F4: 4 | G4: 914.05 | H4: 0.25 | I4: Credit Card | J4: 2742.15
A5: SALE3 | B5: 45259 | C5: CUST1346 | D5: PROD76 | E5: STORE8 | F5: 1 | G5: 921.51 | H5: 0.16 | I5: COD | J5: 774.0684
A6: SALE4 | B6: 45297 | C6: CUST1493 | D6: PROD59 | E6: STORE5 | F6: 3 | G6: 745.3 | H6: 0.18 | I6: Credit Card | J6: 1833.438
A7: SALE5 | B7: 45499 | C7: CUST1116 | D7: PROD15 | E7: STORE7 | F7: 3 | G7: 147.01 | H7: 0.19 | I7: COD | J7: 357.2343
A8: SALE6 | B8: 45850 | C8: CUST1016 | D8: PROD56 | E8: STORE4 | F8: 2 | G8: 785.31 | H8: 0.15 | I8: PayPal | J8: 1335.027
A9: SALE7 | B9: 45248 | C9: CUST1152 | D9: PROD70 | E9: STORE8 | F9: 4 | G9: 342.39 | H9: 0.23 | I9: PayPal | J9: 1054.5612
A10: SALE8 | B10: 45781 | C10: CUST1187 | D10: PROD99 | E10: STORE5 | F10: =Table5[[#This Row],[Total_Amount]]/(G10*(1-Table5[[#This Row],[Discount]])) -> 3 | G10: 448.25 | H10: 0.07 | I10: PayPal | J10: 1250.6175
A11: SALE9 | B11: 45869 | C11: CUST1464 | D11: PROD33 | E11: STORE0 | F11: =Table5[[#This Row],[Total_Amount]]/(G11*(1-Table5[[#This Row],[Discount]])) -> 2 | G11: 873.17 | H11: 0.23 | I11: PayPal | J11: 1344.6818
A12: SALE10 | B12: 45335 | C12: CUST1065 | D12: PROD24 | E12: STORE14 | F12: =Table5[[#This Row],[Total_Amount]]/(G12*(1-Table5[[#This Row],[Discount]])) -> 1 | G12: 278.63 | H12: 0.07 | I12: Credit Card | J12: 259.1259
A13: SALE11 | B13: 45801 | C13: CUST1320 | D13: PROD39 | E13: STORE1 | F13: =Table5[[#This Row],[Total_Amount]]/(G13*(1-Table5[[#This Row],[Discount]])) -> 4 | G13: 286.92 | H13: 0.17 | I13: Credit Card | J13: 952.5744
A14: SALE12 | B14: 45528 | C14: CUST1237 | D14: PROD88 | E14: STORE4 | F14: =Table5[[#This Row],[Total_Amount]]/(G14*(1-Table5[[#This Row],[Discount]])) -> 4 | G14: 644.58 | H14: 0.01 | I14: Credit Card | J14: 2552.5368
A15: SALE13 | B15: 45875 | C15: CUST1443 | D15: PROD34 | E15: STORE16 | F15: =Table5[[#This Row],[Total_Amount]]/(G15*(1-Table5[[#This Row],[Discount]])) -> 2 | G15: 316.9 | H15: 0.3 | I15: PayPal | J15: 443.66
A16: SALE14 | B16: 45829 | C16: CUST1348 | D16: PROD24 | E16: STORE15 | F16: =Table5[[#This Row],[Total_Amount]]/(G16*(1-Table5[[#This Row],[Discount]])) -> 4 | G16: 403.47 | H16: 0.29 | I16: PayPal | J16: 1145.8548
A17: SALE15 | B17: 45636 | C17: CUST1435 | D17: PROD36 | E17: STORE9 | F17: =Table5[[#This Row],[Total_Amount]]/(G17*(1-Table5[[#This Row],[Discount]])) -> 3 | G17: 871.34 | H17: 0.04 | I17: COD | J17: 2509.4592
A18: SALE16 | B18: 45913 | C18: CUST1276 | D18: PROD65 | E18: STORE19 | F18: =Table5[[#This Row],[Total_Amount]]/(G18*(1-Table5[[#This Row],[Discount]])) -> 2 | G18: 451.98 | H18: 0.25 | I18: Credit Card | J18: 677.97
A19: SALE17 | B19: 45637 | C19: CUST1079 | D19: PROD27 | E19: STORE4 | F19: =Table5[[#This Row],[Total_Amount]]/(G19*(1-Table5[[#This Row],[Discount]])) -> 2 | G19: 502.69 | H19: 0.23 | I19: Credit Card | J19: 774.1426
A20: SALE18 | B20: 45517 | C20: CUST1094 | D20: PROD39 | E20: STORE4 | F20: =Table5[[#This Row],[Total_Amount]]/(G20*(1-Table5[[#This Row],[Discount]])) -> 2 | G20: 559.23 | H20: 0.25 | I20: COD | J20: 838.845
A21: SALE19 | B21: 45369 | C21: CUST1239 | D21: PROD60 | E21: STORE13 | F21: Uknown | G21: Unknown | H21: 0.04 | I21: COD | J21: 1782.4512
A22: SALE20 | B22: 45843 | C22: CUST1144 | D22: PROD72 | E22: STORE17 | F22: =Table5[[#This Row],[Total_Amount]]/(G22*(1-Table5[[#This Row],[Discount]])) -> 3 | G22: 986.04 | H22: 0.27 | I22: COD | J22: 2159.4276
A23: SALE21 | B23: 45447 | C23: CUST1396 | D23: PROD43 | E23: STORE18 | F23: =Table5[[#This Row],[Total_Amount]]/(G23*(1-Table5[[#This Row],[Discount]])) -> 1 | G23: 589.56 | H23: 0.22 | I23: Credit Card | J23: 459.8568
A24: SALE22 | B24: 45394 | C24: CUST1476 | D24: PROD69 | E24: STORE10 | F24: =Table5[[#This Row],[Total_Amount]]/(G24*(1-Table5[[#This Row],[Discount]])) -> 3 | G24: 979.42 | H24: 0.03 | I24: PayPal | J24: 2850.1122
A25: SALE23 | B25: 45466 | C25: CUST1368 | D25: PROD12 | E25: STORE8 | F25: =Table5[[#This Row],[Total_Amount]]/(G25*(1-Table5[[#This Row],[Discount]])) -> 1 | G25: 719.28 | H25: 0.08 | I25: Credit Card | J25: 661.7376
A26: SALE24 | B26: 45908 | C26: CUST1186 | D26: PROD67 | E26: STORE6 | F26: =Table5[[#This Row],[Total_Amount]]/(G26*(1-Table5[[#This Row],[Discount]])) -> 3 | G26: 77.6 | H26: 0.07 | I26: Credit Card | J26: 216.504
A27: SALE25 | B27: 45552 | C27: CUST1381 | D27: PROD5 | E27: STORE3 | F27: =Table5[[#This Row],[Total_Amount]]/(G27*(1-Table5[[#This Row],[Discount]])) -> 4 | G27: 852.71 | H27: 0.14 | I27: PayPal | J27: 2933.3224
A28: SALE26 | B28: 45294 | C28: CUST1213 | D28: PROD98 | E28: STORE8 | F28: Uknown | G28: 156.16 | H28: Unknown | I28: Credit Card | J28: 599.6544
A29: SALE27 | B29: 45710 | C29: CUST1200 | D29: PROD77 | E29: STORE8 | F29: =Table5[[#This Row],[Total_Amount]]/(G29*(1-Table5[[#This Row],[Discount]])) -> 3 | G29: 815.49 | H29: 0.17 | I29: Credit Card | J29: 2030.5701
A30: SALE28 | B30: 45923 | C30: CUST1148 | D30: PROD13 | E30: STORE2 | F30: =Table5[[#This Row],[Total_Amount]]/(G30*(1-Table5[[#This Row],[Discount]])) -> 2 | G30: 74.21 | H30: 0.11 | I30: PayPal | J30: 132.0938
A31: SALE29 | B31: 45302 | C31: CUST1348 | D31: PROD99 | E31: STORE3 | F31: =Table5[[#This Row],[Total_Amount]]/(G31*(1-Table5[[#This Row],[Discount]])) -> 4 | G31: 451.67 | H31: 0.15 | I31: Credit Card | J31: 1535.678
A32: SALE30 | B32: 45217 | C32: CUST1028 | D32: PROD5 | E32: STORE19 | F32: =Table5[[#This Row],[Total_Amount]]/(G32*(1-Table5[[#This Row],[Discount]])) -> 1 | G32: 429.38 | H32: 0.13 | I32: PayPal | J32: 373.5606
A33: SALE31 | B33: 45593 | C33: CUST1412 | D33: PROD53 | E33: STORE12 | F33: =Table5[[#This Row],[Total_Amount]]/(G33*(1-Table5[[#This Row],[Discount]])) -> 2 | G33: 148.96 | H33: 0.03 | I33: COD | J33: 288.9824
A34: SALE32 | B34: 45597 | C34: CUST1398 | D34: PROD75 | E34: STORE8 | F34: =Table5[[#This Row],[Total_Amount]]/(G34*(1-Table5[[#This Row],[Discount]])) -> 4 | G34: 313.83 | H34: 0.08 | I34: Credit Card | J34: 1154.8944
A35: SALE33 | B35: 45620 | C35: CUST1453 | D35: PROD12 | E35: STORE6 | F35: =Table5[[#This Row],[Total_Amount]]/(G35*(1-Table5[[#This Row],[Discount]])) -> 2 | G35: 717.31 | H35: 0.15 | I35: Credit Card | J35: 1219.427
A36: SALE34 | B36: 45215 | C36: CUST1344 | D36: PROD79 | E36: STORE1 | F36: =Table5[[#This Row],[Total_Amount]]/(G36*(1-Table5[[#This Row],[Discount]])) -> 3 | G36: 873.22 | H36: 0.18 | I36: Credit Card | J36: 2148.1212
A37: SALE35 | B37: 45878 | C37: CUST1218 | D37: PROD16 | E37: STORE3 | F37: =Table5[[#This Row],[Total_Amount]]/(G37*(1-Table5[[#This Row],[Discount]])) -> 4 | G37: 109.36 | H37: 0.19 | I37: COD | J37: 354.3264
A38: SALE36 | B38: 45635 | C38: CUST1086 | D38: PROD5 | E38: STORE7 | F38: =Table5[[#This Row],[Total_Amount]]/(G38*(1-Table5[[#This Row],[Discount]])) -> 3 | G38: 559.52 | H38: 0.16 | I38: PayPal | J38: 1409.9904
A39: SALE37 | B39: 45329 | C39: CUST1492 | D39: PROD10 | E39: STORE17 | F39: =Table5[[#This Row],[Total_Amount]]/(G39*(1-Table5[[#This Row],[Discount]])) -> 3 | G39: 121.76 | H39: 0.27 | I39: PayPal | J39: 266.6544
A40: SALE38 | B40: 45378 | C40: CUST1189 | D40: PROD33 | E40: STORE13 | F40: =Table5[[#This Row],[Total_Amount]]/(G40*(1-Table5[[#This Row],[Discount]])) -> 4 | G40: 735.32 | H40: 0.06 | I40: COD | J40: 2764.8032
...

Sheet Clean Sales_vlook up
A1: Sales_ID | B1: Order_Date | C1: Customer_ID | D1: Product_ID | E1: Store_ID | F1: Store name | G1: Product name | H1: Category | I1: Region | J1: Customer Name | K1: Quantity | L1: Unit_Price | M1: Discount | N1: Payment_Type | O1: Total_Amount
A2: SALE0 | B2: 45480 | C2: CUST1409 | D2: PROD97 | E2: STORE3 | F2: =[1]Raw_Customer_Dim!$A$2 -> CUST1000 | G2: =_xlfn.XLOOKUP(E2,Store_Dim!A:A,Store_Dim!B:B,"Not Found") -> Johnson-Wright | H2: =_xlfn.XLOOKUP(D2,Product_Dim!A:A,Product_Dim!C:C,"Not Found") -> Sports | I2: =_xlfn.XLOOKUP(E2,Store_Dim!A:A,Store_Dim!C:C,"Not Found") -> North | J2: =_xlfn.XLOOKUP(C2,Customer_Dim!A:A,Customer_Dim!B:B,"Not Found") -> Sarah Smith | K2: 1 | L2: 218.04 | M2: 0.09 | N2: Credit Card | O2: 198.4164 | Q2: Sales
A3: SALE1 | B3: 45285 | C3: CUST1467 | D3: PROD74 | E3: STORE17 | F3: =[1]Raw_Customer_Dim!$A$2 -> CUST1000 | G3: =_xlfn.XLOOKUP(E3,Store_Dim!A:A,Store_Dim!B:B,"Not Found") -> Holloway Ltd | H3: =_xlfn.XLOOKUP(D3,Product_Dim!A:A,Product_Dim!C:C,"Not Found") -> Electronics | I3: =_xlfn.XLOOKUP(E3,Store_Dim!A:A,Store_Dim!C:C,"Not Found") -> North | J3: =_xlfn.XLOOKUP(C3,Customer_Dim!A:A,Customer_Dim!B:B,"Not Found") -> Michael Foley | K3: 3 | L3: 104.47 | M3: 0.27 | N3: PayPal | O3: 228.7893 | Q3: tools | R3: result
A4: SALE2 | B4: 45446 | C4: CUST1056 | D4: PROD49 | E4: STORE8 | F4: =[1]Raw_Customer_Dim!$A$2 -> CUST1000 | G4: =_xlfn.XLOOKUP(E4,Store_Dim!A:A,Store_Dim!B:B,"Not Found") -> Bean, Jones and Park | H4: =_xlfn.XLOOKUP(D4,Product_Dim!A:A,Product_Dim!C:C,"Not Found") -> Beauty | I4: =_xlfn.XLOOKUP(E4,Store_Dim!A:A,Store_Dim!C:C,"Not Found") -> West | J4: =_xlfn.XLOOKUP(C4,Customer_Dim!A:A,Customer_Dim!B:B,"Not Found") -> Christopher Sutton | K4: 4 | L4: 914.05 | M4: 0.25 | N4: Credit Card | O4: 2742.15 | Q4: Sum | R4: =SUM(Table511[[#All],[Total_Amount]]) -> 2170907.5
A5: SALE3 | B5: 45259 | C5: CUST1346 | D5: PROD76 | E5: STORE8 | F5: =[1]Raw_Customer_Dim!$A$2 -> CUST1000 | G5: =_xlfn.XLOOKUP(E5,Store_Dim!A:A,Store_Dim!B:B,"Not Found") -> Bean, Jones and Park | H5: =_xlfn.XLOOKUP(D5,Product_Dim!A:A,Product_Dim!C:C,"Not Found") -> Electronics | I5: =_xlfn.XLOOKUP(E5,Store_Dim!A:A,Store_Dim!C:C,"Not Found") -> West | J5: =_xlfn.XLOOKUP(C5,Customer_Dim!A:A,Customer_Dim!B:B,"Not Found") -> John Jordan | K5: 1 | L5: 921.51 | M5: 0.16 | N5: COD | O5: 774.0684 | Q5: Mean | R5: =AVERAGE(Table511[Total_Amount]) -> 1087.629
A6: SALE4 | B6: 45297 | C6: CUST1493 | D6: PROD59 | E6: STORE5 | F6: =[1]Raw_Customer_Dim!$A$2 -> CUST1000 | G6: =_xlfn.XLOOKUP(E6,Store_Dim!A:A,Store_Dim!B:B,"Not Found") -> Gray Ltd | H6: =_xlfn.XLOOKUP(D6,Product_Dim!A:A,Product_Dim!C:C,"Not Found") -> Beauty | I6: =_xlfn.XLOOKUP(E6,Store_Dim!A:A,Store_Dim!C:C,"Not Found") -> North | J6: =_xlfn.XLOOKUP(C6,Customer_Dim!A:A,Customer_Dim!B:B,"Not Found") -> Amanda Powell | K6: 3 | L6: 745.3 | M6: 0.18 | N6: Credit Card | O6: 1833.438 | Q6: Median | R6: =MEDIAN(Table511[Total_Amount]) -> 868.7182
A7: SALE5 | B7: 45499 | C7: CUST1116 | D7: PROD15 | E7: STORE7 | F7: =[1]Raw_Customer_Dim!$A$2 -> CUST1000 | G7: =_xlfn.XLOOKUP(E7,Store_Dim!A:A,Store_Dim!B:B,"Not Found") -> Martinez-Mullins | H7: =_xlfn.XLOOKUP(D7,Product_Dim!A:A,Product_Dim!C:C,"Not Found") -> Electronics | I7: =_xlfn.XLOOKUP(E7,Store_Dim!A:A,Store_Dim!C:C,"Not Found") -> South | J7: =_xlfn.XLOOKUP(C7,Customer_Dim!A:A,Customer_Dim!B:B,"Not Found") -> Anthony Phillips | K7: 3 | L7: 147.01 | M7: 0.19 | N7: COD | O7: 357.2343 | Q7: Standard Deviation | R7: =_xlfn.STDEV.P(Table511[Total_Amount]) -> 819.9203
A8: SALE6 | B8: 45850 | C8: CUST1016 | D8: PROD56 | E8: STORE4 | F8: =[1]Raw_Customer_Dim!$A$2 -> CUST1000 | G8: =_xlfn.XLOOKUP(E8,Store_Dim!A:A,Store_Dim!B:B,"Not Found") -> Alexander Group | H8: =_xlfn.XLOOKUP(D8,Product_Dim!A:A,Product_Dim!C:C,"Not Found") -> Home | I8: =_xlfn.XLOOKUP(E8,Store_Dim!A:A,Store_Dim!C:C,"Not Found") -> South | J8: =_xlfn.XLOOKUP(C8,Customer_Dim!A:A,Customer_Dim!B:B,"Not Found") -> John Scott | K8: 2 | L8: 785.31 | M8: 0.15 | N8: PayPal | O8: 1335.027 | Q8: Min | R8: =MIN(Table511[[#All],[Total_Amount]]) -> 18.459
A9: SALE7 | B9: 45248 | C9: CUST1152 | D9: PROD70 | E9: STORE8 | F9: =[1]Raw_Customer_Dim!$A$2 -> CUST1000 | G9: =_xlfn.XLOOKUP(E9,Store_Dim!A:A,Store_Dim!B:B,"Not Found") -> Bean, Jones and Park | H9: =_xlfn.XLOOKUP(D9,Product_Dim!A:A,Product_Dim!C:C,"Not Found") -> Home | I9: =_xlfn.XLOOKUP(E9,Store_Dim!A:A,Store_Dim!C:C,"Not Found") -> West | J9: =_xlfn.XLOOKUP(C9,Customer_Dim!A:A,Customer_Dim!B:B,"Not Found") -> Patrick Roberts | K9: 4 | L9: 342.39 | M9: 0.23 | N9: PayPal | O9: 1054.5612 | Q9: Max | R9: =MAX(Table511[[#All],[Total_Amount]]) -> 3908.2428
A10: SALE8 | B10: 45781 | C10: CUST1187 | D10: PROD99 | E10: STORE5 | F10: =[1]Raw_Customer_Dim!$A$2 -> CUST1000 | G10: =_xlfn.XLOOKUP(E10,Store_Dim!A:A,Store_Dim!B:B,"Not Found") -> Gray Ltd | H10: =_xlfn.XLOOKUP(D10,Product_Dim!A:A,Product_Dim!C:C,"Not Found") -> Home | I10: =_xlfn.XLOOKUP(E10,Store_Dim!A:A,Store_Dim!C:C,"Not Found") -> North | J10: =_xlfn.XLOOKUP(C10,Customer_Dim!A:A,Customer_Dim!B:B,"Not Found") -> Dr. Suzanne Bullock | K10: =Table511[[#This Row],[Total_Amount]]/(L10*(1-Table511[[#This Row],[Discount]])) -> 3 | L10: 448.25 | M10: 0.07 | N10: PayPal | O10: 1250.6175 | Q10: Average | R10: =AVERAGE(Table511[[#All],[Total_Amount]]) -> 1087.629
A11: SALE9 | B11: 45869 | C11: CUST1464 | D11: PROD33 | E11: STORE0 | F11: =[1]Raw_Customer_Dim!$A$2 -> CUST1000 | G11: =_xlfn.XLOOKUP(E11,Store_Dim!A:A,Store_Dim!B:B,"Not Found") -> Rivera-Warner | H11: =_xlfn.XLOOKUP(D11,Product_Dim!A:A,Product_Dim!C:C,"Not Found") -> Home | I11: =_xlfn.XLOOKUP(E11,Store_Dim!A:A,Store_Dim!C:C,"Not Found") -> East | J11: =_xlfn.XLOOKUP(C11,Customer_Dim!A:A,Customer_Dim!B:B,"Not Found") -> Not Found | K11: =Table511[[#This Row],[Total_Amount]]/(L11*(1-Table511[[#This Row],[Discount]])) -> 2 | L11: 873.17 | M11: 0.23 | N11: PayPal | O11: 1344.6818 | Q11: mode of quantity | R11: =_xlfn.MODE.SNGL(K:K) -> 2
A12: SALE10 | B12: 45335 | C12: CUST1065 | D12: PROD24 | E12: STORE14 | F12: =[1]Raw_Customer_Dim!$A$2 -> CUST1000 | G12: =_xlfn.XLOOKUP(E12,Store_Dim!A:A,Store_Dim!B:B,"Not Found") -> Mcdonald Inc | H12: =_xlfn.XLOOKUP(D12,Product_Dim!A:A,Product_Dim!C:C,"Not Found") -> Sports | I12: =_xlfn.XLOOKUP(E12,Store_Dim!A:A,Store_Dim!C:C,"Not Found") -> South | J12: =_xlfn.XLOOKUP(C12,Customer_Dim!A:A,Customer_Dim!B:B,"Not Found") -> Michael Thomas | K12: =Table511[[#This Row],[Total_Amount]]/(L12*(1-Table511[[#This Row],[Discount]])) -> 1 | L12: 278.63 | M12: 0.07 | N12: Credit Card | O12: 259.1259
A13: SALE11 | B13: 45801 | C13: CUST1320 | D13: PROD39 | E13: STORE1 | F13: =[1]Raw_Customer_Dim!$A$2 -> CUST1000 | G13: =_xlfn.XLOOKUP(E13,Store_Dim!A:A,Store_Dim!B:B,"Not Found") -> Martinez, Adkins and Johnson | H13: =_xlfn.XLOOKUP(D13,Product_Dim!A:A,Product_Dim!C:C,"Not Found") -> Electronics | I13: =_xlfn.XLOOKUP(E13,Store_Dim!A:A,Store_Dim!C:C,"Not Found") -> North | J13: =_xlfn.XLOOKUP(C13,Customer_Dim!A:A,Customer_Dim!B:B,"Not Found") -> Jessica Gonzalez | K13: =Table511[[#This Row],[Total_Amount]]/(L13*(1-Table511[[#This Row],[Discount]])) -> 4 | L13: 286.92 | M13: 0.17 | N13: Credit Card | O13: 952.5744
A14: SALE12 | B14: 45528 | C14: CUST1237 | D14: PROD88 | E14: STORE4 | F14: =[1]Raw_Customer_Dim!$A$2 -> CUST1000 | G14: =_xlfn.XLOOKUP(E14,Store_Dim!A:A,Store_Dim!B:B,"Not Found") -> Alexander Group | H14: =_xlfn.XLOOKUP(D14,Product_Dim!A:A,Product_Dim!C:C,"Not Found") -> Sports | I14: =_xlfn.XLOOKUP(E14,Store_Dim!A:A,Store_Dim!C:C,"Not Found") -> South | J14: =_xlfn.XLOOKUP(C14,Customer_Dim!A:A,Customer_Dim!B:B,"Not Found") -> Wesley Short | K14: =Table511[[#This Row],[Total_Amount]]/(L14*(1-Table511[[#This Row],[Discount]])) -> 4 | L14: 644.58 | M14: 0.01 | N14: Credit Card | O14: 2552.5368
A15: SALE13 | B15: 45875 | C15: CUST1443 | D15: PROD34 | E15: STORE16 | F15: =[1]Raw_Customer_Dim!$A$2 -> CUST1000 | G15: =_xlfn.XLOOKUP(E15,Store_Dim!A:A,Store_Dim!B:B,"Not Found") -> Frederick-Wright | H15: =_xlfn.XLOOKUP(D15,Product_Dim!A:A,Product_Dim!C:C,"Not Found") -> Electronics | I15: =_xlfn.XLOOKUP(E15,Store_Dim!A:A,Store_Dim!C:C,"Not Found") -> West | J15: =_xlfn.XLOOKUP(C15,Customer_Dim!A:A,Customer_Dim!B:B,"Not Found") -> Adam Castro | K15: =Table511[[#This Row],[Total_Amount]]/(L15*(1-Table511[[#This Row],[Discount]])) -> 2 | L15: 316.9 | M15: 0.3 | N15: PayPal | O15: 443.66
A16: SALE14 | B16: 45829 | C16: CUST1348 | D16: PROD24 | E16: STORE15 | F16: =[1]Raw_Customer_Dim!$A$2 -> CUST1000 | G16: =_xlfn.XLOOKUP(E16,Store_Dim!A:A,Store_Dim!B:B,"Not Found") -> Shelton PLC | H16: =_xlfn.XLOOKUP(D16,Product_Dim!A:A,Product_Dim!C:C,"Not Found") -> Sports | I16: =_xlfn.XLOOKUP(E16,Store_Dim!A:A,Store_Dim!C:C,"Not Found") -> North | J16: =_xlfn.XLOOKUP(C16,Customer_Dim!A:A,Customer_Dim!B:B,"Not Found") -> Sherry Cabrera | K16: =Table511[[#This Row],[Total_Amount]]/(L16*(1-Table511[[#This Row],[Discount]])) -> 4 | L16: 403.47 | M16: 0.29 | N16: PayPal | O16: 1145.8548
A17: SALE15 | B17: 45636 | C17: CUST1435 | D17: PROD36 | E17: STORE9 | F17: =[1]Raw_Customer_Dim!$A$2 -> CUST1000 | G17: =_xlfn.XLOOKUP(E17,Store_Dim!A:A,Store_Dim!B:B,"Not Found") -> Moore, Padilla and Butler | H17: =_xlfn.XLOOKUP(D17,Product_Dim!A:A,Product_Dim!C:C,"Not Found") -> Clothing | I17: =_xlfn.XLOOKUP(E17,Store_Dim!A:A,Store_Dim!C:C,"Not Found") -> South | J17: =_xlfn.XLOOKUP(C17,Customer_Dim!A:A,Customer_Dim!B:B,"Not Found") -> Lindsay Beasley | K17: =Table511[[#This Row],[Total_Amount]]/(L17*(1-Table511[[#This Row],[Discount]])) -> 3 | L17: 871.34 | M17: 0.04 | N17: COD | O17: 2509.4592
A18: SALE16 | B18: 45913 | C18: CUST1276 | D18: PROD65 | E18: STORE19 | F18: =[1]Raw_Customer_Dim!$A$2 -> CUST1000 | G18: =_xlfn.XLOOKUP(E18,Store_Dim!A:A,Store_Dim!B:B,"Not Found") -> Mann-Austin | H18: =_xlfn.XLOOKUP(D18,Product_Dim!A:A,Product_Dim!C:C,"Not Found") -> Sports | I18: =_xlfn.XLOOKUP(E18,Store_Dim!A:A,Store_Dim!C:C,"Not Found") -> East | J18: =_xlfn.XLOOKUP(C18,Customer_Dim!A:A,Customer_Dim!B:B,"Not Found") -> Arthur Warren | K18: =Table511[[#This Row],[Total_Amount]]/(L18*(1-Table511[[#This Row],[Discount]])) -> 2 | L18: 451.98 | M18: 0.25 | N18: Credit Card | O18: 677.97
A19: SALE17 | B19: 45637 | C19: CUST1079 | D19: PROD27 | E19: STORE4 | F19: =[1]Raw_Customer_Dim!$A$2 -> CUST1000 | G19: =_xlfn.XLOOKUP(E19,Store_Dim!A:A,Store_Dim!B:B,"Not Found") -> Alexander Group | H19: =_xlfn.XLOOKUP(D19,Product_Dim!A:A,Product_Dim!C:C,"Not Found") -> Home | I19: =_xlfn.XLOOKUP(E19,Store_Dim!A:A,Store_Dim!C:C,"Not Found") -> South | J19: =_xlfn.XLOOKUP(C19,Customer_Dim!A:A,Customer_Dim!B:B,"Not Found") -> Molly Gardner | K19: =Table511[[#This Row],[Total_Amount]]/(L19*(1-Table511[[#This Row],[Discount]])) -> 2 | L19: 502.69 | M19: 0.23 | N19: Credit Card | O19: 774.1426
A20: SALE18 | B20: 45517 | C20: CUST1094 | D20: PROD39 | E20: STORE4 | F20: =[1]Raw_Customer_Dim!$A$2 -> CUST1000 | G20: =_xlfn.XLOOKUP(E20,Store_Dim!A:A,Store_Dim!B:B,"Not Found") -> Alexander Group | H20: =_xlfn.XLOOKUP(D20,Product_Dim!A:A,Product_Dim!C:C,"Not Found") -> Electronics | I20: =_xlfn.XLOOKUP(E20,Store_Dim!A:A,Store_Dim!C:C,"Not Found") -> South | J20: =_xlfn.XLOOKUP(C20,Customer_Dim!A:A,Customer_Dim!B:B,"Not Found") -> David Patterson | K20: =Table511[[#This Row],[Total_Amount]]/(L20*(1-Table511[[#This Row],[Discount]])) -> 2 | L20: 559.23 | M20: 0.25 | N20: COD | O20: 838.845
